Workbook
Name \5: #REF!
Name \5: 'Cuadro 5'!#REF!
Name \5: #REF!
Name \6: #REF!
Name \6: 'Cuadro 5'!#REF!
Name \6: #REF!
Name \7: #REF!
Name \7: 'Cuadro 5'!#REF!
Name \7: #REF!
Name \A: #REF!
Name \A: 'Cuadro 5'!#REF!
Name \A: #REF!
Name \B: #REF!
Name \B: 'Cuadro 5'!#REF!
Name \B: #REF!
Name \C: #REF!
Name \C: 'Cuadro 5'!#REF!
Name \C: #REF!
Name \D: #REF!
Name \D: 'Cuadro 5'!#REF!
Name \D: #REF!
Name \E: #REF!
Name \E: 'Cuadro 5'!#REF!
Name \E: #REF!
Name \F: #REF!
Name \F: 'Cuadro 5'!#REF!
Name \F: #REF!
Name \I: #REF!
Name \I: #REF!
Name \I2: #REF!
Name \I2: #REF!
Name \K: #REF!
Name \K: 'Cuadro 5'!#REF!
Name \K: #REF!
Name \L: #REF!
Name \L: 'Cuadro 5'!#REF!
Name \L: #REF!
Name \P: #REF!
Name \P: #REF!
Name \Z: #REF!
Name \Z: 'Cuadro 5'!#REF!
Name \Z: #REF!
Name __123Graph_A: #REF!
Name __123Graph_A: #REF!
Name __123Graph_ABERLGRAP: 'Cuadro 5'!#REF!
Name __123Graph_ABERLGRAP: #REF!
Name __123Graph_ABKSRESRV: 'Cuadro 5'!#REF!
Name __123Graph_ABKSRESRV: #REF!
Name __123Graph_ACATCH1: 'Cuadro 5'!#REF!
Name __123Graph_ACATCH1: #REF!
Name __123Graph_AChart1: 'Cuadro 5'!#REF!
Name __123Graph_AChart1: #REF!
Name __123Graph_AChart2: 'Cuadro 5'!#REF!
Name __123Graph_AChart2: #REF!
Name __123Graph_AChart3: 'Cuadro 5'!#REF!
Name __123Graph_AChart3: #REF!
Name __123Graph_ACONVERG1: 'Cuadro 5'!#REF!
Name __123Graph_ACONVERG1: #REF!
Name __123Graph_ACurrent: 'Cuadro 5'!#REF!
Name __123Graph_ACurrent: #REF!

Sheet Cuadros
B2: ESTUDIO DE EVALUACIÓN DE LA REGLA DE GASTO EN PENSIONES
B6: Capítulo | C6: Título Nivel 1 | D6: Título Nivel 2 | E6: Página | F6: Hoja | G6: Título | H6: Fuente
B8: RESUMEN EJECUTIVO | E8: 6 | F8: Cuadro 1 | G8: Impacto medio anual de las medidas adoptadas a partir de 2020 para fortalecer los ingresos del sistema público de pensiones (% PIB)
E9: 7 | F9: Cuadro 2 | G9: Gasto bruto público en pensiones neto de medidas de ingresos (% PIB)
B10: 2. REGLA DE GASTO EN PENSIONES | C10: 2.3. Evaluación del impacto de las medidas de ingresos | E10: 19 | F10: Cuadro 3 | G10: Impacto medio anual de las medidas adoptadas a partir de 2020 para fortalecer los ingresos del sistema público de pensiones (% PIB)
D11: 2.3.2. Medidas indirectas de ingresos | E11: 29 | F11: Cuadro 4 | G11: Comparación del impacto estimado del SMI sobre el empleo
E12: 30 | F12: Cuadro 5 | G12: Impacto del incremento del salario mínimo interprofesional (desviaciones respecto al escenario sin medidas, % y puntos porcentuales)
E13: 33 | F13: Cuadro 6 | G13: Comparación del impacto estimado de las medidas laborales sobre las transiciones laborales
E14: 34 | F14: Cuadro 7 | G14: Impacto de las medidas de mercado laboral (desviaciones respecto al escenario sin medidas, % y puntos porcentuales)
C15: 2.4. Resultado de la regla de gasto en pensiones | E15: 52 | F15: Cuadro 8 | G15: Gasto bruto público en pensiones neto de medidas de ingresos (% PIB)
C16: 2.5. Encaje de la regla de gasto de pensiones con el marco fiscal | E16: 52 | F16: Cuadro 9 | G16: Cuenta de control anual y acumulada de la regla de gasto europea
E17: 53 | F17: Cuadro 10 | G17: Gasto primario neto de medidas de ingresos por subsectores (% variación)
B18: 3. SUPUESTOS DEMOGRÁFICOS Y MACROECONÓMICOS | C18: 3.1. Proyecciones demográficas de la AIReF | E18: 57 | F18: Cuadro 11 | G18: Comparativa de las proyecciones demográficas de la AIReF con las de otros organismos para diversos años
B19: 4. ESCENARIO FISCAL A LARGO PLAZO | C19: 4.2 Evolución de los empleos de las Administraciones Públicas | E19: 65 | F19: Cuadro 12 | G19: Empleos no financieros sin PRTR (% PIB)
B20: ANEXO I. ACTUALIZACIÓN DE LAS PROYECCIONES DE POBLACIÓN DE RESIDENTES 2026-2050 | C20: Anexo I. 3. Proyección de las migraciones | D20: Anexo I. 3.3. Pirámide de población | E20: 94 | F20: Anexo I. Cuadro 1. | G20: Estructura porcentual de la población según tramos etarios

Sheet Gráficos
B2: ESTUDIO DE EVALUACIÓN DE LA REGLA DE GASTO EN PENSIONES
B6: Capítulo | C6: Título Nivel 1 | D6: Título Nivel 2 | E6: Página | F6: Hoja | G6: Título | H6: Fuente
B8: RESUMEN EJECUTIVO | E8: 6 | F8: Gráfico 1 | G8: Gasto bruto público en pensiones (% PIB)
E9: 7 | F9: Gráfico 2 | G9: Deuda pública (% PIB)
E10: 7 | F10: Gráfico 3 | G10: Saldo público (% PIB)
B11: 2. REGLA DE GASTO EN PENSIONES | C11: 2.1. Gasto bruto público en pensiones | E11: 15 | F11: Gráfico 4 | G11: Evolución del gasto en pensiones (% PIB)
E12: 16 | F12: Gráfico 5 | G12: Descomposición del crecimiento del gasto en pensiones
E13: 16 | F13: Gráfico 6 | G13: Número de pensiones (millones)
E14: 17 | F14: Gráfico 7 | G14: Tasa de generosidad (pensión media/ salario medio)
C15: 2.2. La senda de crecimiento del PIB nominal de la regla de gasto en pensiones | E15: 18 | F15: Gráfico 8. A. | G15: Proyecciones de PIB nominal (miles de millones de euros)
E16: 18 | F16: Gráfico 8. B. | G16: Proyecciones de población (miles de residentes)
C17: 2.3. Evaluación del impacto de las medidas de ingresos | D17: 2.3.2. Medidas indirectas de ingresos | E17: 27 | F17: Gráfico 9 | G17: Incidencia del SMI (porcentaje de trabajadores sobre el total de afiliados al régimen general). 2018-2024
E18: 28 | F18: Gráfico 10 | G18: Distribución de las bases de cotización mensuales, 2018, 2023 y 2024
E19: 32 | F19: Gráfico 11. A. | G19: Salida del no empleo al empleo
E20: 32 | F20: Gráfico 11. B. | G20: Salida del empleo al no empleo
B21: RECUADRO 2. LA REGULACIÓN EXTRAORDINARIA. UNA ESTIMACIÓN TENTATIVA DE SU IMPACTO EN COTIZACIONES | E21: 45 | F21: Gráfico RE_2. 1. | G21: Tasa de parcialidad por sexo y origen de los inmigrantes (%)
E22: 45 | F22: Gráfico RE_2. 2. | G22: Estimación flujos personas regularizables DA21
E23: 46 | F23: Gráfico RE 2. 3. | G23: Afiliados extranjeros en 2005: observado vs. contrafactual (miles)
E24: 47 | F24: Gráfico RE_2.4. | G24: Base media anual de cotización de inmigrantes (miles de euros)
E25: 51 | F25: Gráfico RE_2.5. | G25: Distribución del impacto potencial de cotizaciones (% PIB) con distintas combinaciones de parámetros para el primer año
C26: 2.5. Encaje de la regla de gasto de pensiones con el marco fiscal | E26: 54 | F26: Gráfico 12 | G26: Fuentes de financiación del sistema público de pensiones
B27: 3. SUPUESTOS DEMOGRÁFICOS Y MACROECONÓMICOS | C27: 3.1. Proyecciones demográficas de la AIReF | E27: 56 | F27: Gráfico 13. A. | G27: Población total
E28: 56 | F28: Gráfico 13. B. | G28: Población de 15-74 años
E29: 58 | F29: Gráfico 14. A. | G29: Descomposición de la tasa de dependencia
E30: 58 | F30: Gráfico 14. B. | G30: Comparativa de tasas de dependencia
C31: 3. 2. Supuestos macroeconómicos | E31: 59 | F31: Gráfico 15 | G31: Crecimiento promedio del PIB potencial (% 2022-2050)
E32: 60 | F32: Gráfico 16 | G32: Tasa de participación (% población 15-74 años)
E33: 50 | F33: Gráfico 17 | G33: Nawru (%)
B34: 4. ESCENARIO FISCAL A LARGO PLAZO | C34: 4.1. Evolución de los recursos de las Administraciones públicas | E34: 62 | F34: Gráfico 18 | G34: Evolución de la recaudación impositiva entre 1995 y 2050 (% PIB)
E35: 63 | F35: Gráfico 19 | G35: Evolución de los recursos hasta 2050 (% PIB)
C36: 4.2. Evolución de los empleos de las Administraciones públicas | E36: 65 | F36: Gráfico 20 | G36: Empleos no financieros sin PRTR (% PIB)
E37: 66 | F37: Gráfico 21 | G37: Proyección tipo medio de emisión y tipo implícito
E38: 66 | F38: Gráfico 22 | G38: Intereses (% PIB)
E39: 67 | F39: Gráfico 23 | G39: Evolución del gasto en sanidad (% PIB)
E40: 67 | F40: Gráfico 24 | G40: Evolución del gasto en cuidados de larga duración (% PIB)
E41: 68 | F41: Gráfico 25 | G41: Evolución del gasto en educación (% PIB)
E42: 68 | F42: Gráfico 26 | G42: Evolución del gasto en prestaciones por desempleo (% PIB)
B43: 5. ANÁLISIS DE SOSTENIBILIDAD | E43: 69 | F43: Gráfico 27 | G43: Evolución de la ratio de deuda (% PIB)
E44: 69 | F44: Gráfico 28 | G44: Deuda (% PIB). Países de la Unión Europea con más del 80%.
E45: 70 | F45: Gráfico 29 | G45: Deuda (% PIB)
...

Sheet Cuadro 1 y 3
A1: Índice de cuadros
B3: CUADRO 1. IMPACTO MEDIO ANUAL DE LAS MEDIDAS ADOPTADAS A PARTIR DE 2020 PARA FORTALECER LOS INGRESOS DEL SISTEMA PÚBLICO DE PENSIONES (% PIB)
C5: Impacto hasta 2025 | D5: Impacto promedio 2022-2050
B6: Variación ingresos | C6: 0.92273954 | D6: 1.571092
B7: Mecanismo de Equidad Intergeneracional | C7: 0.29079478 | D7: 0.39115046
B8: Evolución Bases Máximas Cotización | C8: 0.22879191 | D8: 0.31966452
B9: Cotización adicional de solidaridad | C9: 0.019466266 | D9: 0.077498131
B10: Reforma cotizaciones trabajadores autónomos | C10: 0.015128785 | D10: 0.33386648
B11: Transferencias | C11: 0.26855779 | D11: 0.3189124
B12: Incrementos Salario Mínimo Interprofesional | C12: 0.1 | D12: 0.1
B13: Reforma laboral | C13: 0 | D13: 0
B14: Regularización inmigrantes (*) | C14: 0 | D14: 0.03

Sheet Cuadro 2 y 8
A1: Índice de cuadros
B3: CUADRO 2. GASTO PÚBLICO EN PENSIONES NETO DE MEDIDAS DE INGRESOS (% PIB)
B5: Regla de gasto | C5: Gastos | F5: Medidas ingresos | I5: Gasto neto de medidas
C6: Dato | D6: Límite | E6: Cumple | F6: Dato | G6: Límite | H6: Cumple | I6: Dato | J6: Límite | K6: Cumple
B7: AR 2024 actualizado | C7: 14.567182 | D7: 15 | E7: P | F7: 1.571092 | G7: 1.7 | H7: O | I7: 12.99609 | J7: 13.3 | K7: P
B8: AIReF | C8: 14.548278 | D8: 15 | E8: P | F8: 1.571092 | G8: 1.7 | H8: O | I8: 12.977186 | J8: 13.3 | K8: P

Sheet Cuadro 4
A1: Índice de cuadros
B3: CUADRO 4. COMPARACIÓN DEL IMPACTO ESTIMADO DEL SMI SOBRE EL EMPLEO
B7: Concepto | C7: Documento Técnico 9/25 (sept. 2025) | D7: Actualización (mayo 2026)
B8: Subida SMI 2019 (+22,3%)
B9: Impacto sobre la afiliación | C9: Entre −0,25 y −0,41 pp | D9: Entre −0,28 y −0,36 pp
B10: Pérdida de afiliados (Régimen General) | C10: Entre 40.000 y 65.000 | D10: Entre 45.000 y 54.000
B11: Subida SMI 2023 (+8,0%)
B12: Impacto sobre la afiliación | C12: Entre −0,34 y −0,53 pp | D12: Entre −0,32 y −0,39 pp
B13: Pérdida de afiliados (Régimen General) | C13: Entre 55.000 y 85.000 | D13: Entre 50.000 y 61.000
B14: Subida SMI 2024 (+5,0%)
B15: Impacto sobre la afiliación | C15: No estimado | D15: Entre −0,49 y −0,56 pp
B16: Pérdida de afiliados (Régimen General) | C16: — | D16: Entre 78.000 y 90.000
B18: Fuente: AIReF, a partir de la MCVL
B19: Nota: Los rangos corresponden a los intervalos de confianza al 95 % sobre la afiliación en el Régimen General de la Seguridad Social.

Sheet Cuadro 5
A1: Índice de cuadros
B3: CUADRO 5. IMPACTO DEL INCREMENTO DEL SALARIO MÍNIMO INTERPROFESIONAL (DESVIACIONES RESPECTO AL ESCENARIO SIN MEDIDAS, % Y PUNTOS PORCENTUALES)
C5: t+5 | F5: t+10 | I5: Promedio 2022-2050
C6: MTA | D6: MEGAIReF eficiencia | E6: MEGAIReF shifter | F6: MTA | G6: MEGAIReF eficiencia | H6: MEGAIReF shifter | I6: MTA | J6: MEGAIReF eficiencia | K6: MEGAIReF shifter
B7: PIB | C7: 0.0019147146 | D7: 0.12420201 | E7: -0.11272687 | F7: 0.18931288 | G7: 0.17064327 | H7: -0.2374577 | I7: 0.1472604 | J7: 0.16393465 | K7: -0.24645912
B8: Empleo | C8: -0.012035788 | D8: 0.13448714 | E8: -0.27481518 | F8: -0.010111564 | G8: 0.18408118 | H8: -0.34454956 | I8: -0.0094423451 | J8: 0.17540208 | K8: -0.34648359
B9: Saldo Público (% PIB) | C9: 0.1499287 | D9: 0.0085592622 | E9: -0.029580998 | F9: 0.39419135 | G9: 0.0031556252 | H9: -0.05427177 | I9: 0.31037972 | J9: 0.00010525476 | K9: -0.044491712
B10: Cotizaciones | C10: 0.61927022 | D10: 0.11403628 | E10: 0.0037076998 | F10: 1.637295 | G10: 0.15783635 | H10: 0.028395086 | I10: 1.3907428 | J10: 0.1518147 | K10: 0.062636591
B11: Cotizaciones (% PIB) | C11: 0.068838947 | D11: 0 | E11: 0.00096557338 | F11: 0.1598643 | G11: -0.001682056 | H11: 0.0071573888 | I11: 0.12659325 | J11: -0.0015918297 | K11: 0.011137947
B13: Fuente: | C13: AIReF

Sheet Cuadro 6
A1: Índice de cuadros
B3: CUADRO 6. COMPARACIÓN DEL IMPACTO ESTIMADO DE LAS MEDIDAS LABORALES SOBRE LAS TRANSICIONES LABORALES
B5: Transición laboral | C5: Documento Técnico 8/25 (sept. 2025) | D5: Actualización (mayo 2026)
B6: Probabilidad mensual de transición del desempleo al empleo | C6: +0,61 pp | D6: Entre +0,61 y +0,33 pp
B7: Probabilidad mensual de transición del empleo al desempleo | C7: -0,68pp | D7: Entre -0,39 y -0,79 pp

Sheet Cuadro 7
A1: Índice de cuadros
B3: CUADRO 7. IMPACTO DE LAS MEDIDAS DE MERCADO LABORAL (DESVIACIONES RESPECTO AL ESCENARIO SIN MEDIDAS, % Y PUNTOS PORCENTUALES)
C5: t+5 | F5: t+10 | I5: Promedio 2022-2050
C6: MTA | D6: MEGAIReF eficiencia | E6: MEGAIReF shifter | F6: MTA | G6: MEGAIReF eficiencia | H6: MEGAIReF shifter | I6: MTA | J6: MEGAIReF eficiencia | K6: MEGAIReF shifter
B7: PIB | C7: 0.0019147146 | D7: 0.12420201 | E7: 0.12420201 | F7: 0.1 | G7: 0.1 | H7: 0.1 | I7: 0 | J7: 0.1 | K7: 0.1
B8: Empleo | C8: 0.12420201 | D8: 0.12420201 | E8: 0.12420201 | F8: 0.1 | G8: 0.2 | H8: 0.1 | I8: 0.1 | J8: 0.1 | K8: 0.1
B9: Saldo Público (% PIB) | C9: 0.0085592622 | D9: 0.0085592622 | E9: -0.029580998 | F9: 0.1 | G9: 0.1 | H9: 0 | I9: 0 | J9: 0.00010525476 | K9: -0.044491712
B10: Cotizaciones | C10: 0.12420201 | D10: 0.0085592622 | E10: 0.3 | F10: 0.1 | G10: 0 | H10: 0.3 | I10: 0.1 | J10: 0 | K10: 0.3
B11: Cotizaciones (% PIB) | C11: 0 | D11: 0 | E11: 0.00096557338 | F11: 0 | G11: -0.001682056 | H11: 0.0071573888 | I11: 0 | J11: -0.0015918297 | K11: 0.011137947
B13: Fuente: | C13: AIReF

Sheet Cuadro 9
A1: Índice de cuadros
B3: CUADRO 9. CUENTA DE CONTROL ANUAL Y ACUMULADA DE LA REGLA DE GASTO EUROPEA (%PIB)
B5: Cuenta de control | C5: 2024 | E5: 2025 | G5: 2026 | I5: 2027 | K5: 2028
B6: Anual | C6: 0.45045555 | D6: P | E6: -0.44098201 | F6: O | G6: -0.91380644 | H6: O | I6: -0.78747132 | J6: O | K6: -0.49827993 | L6: O
B7: Acumulada | C7: 0.45045555 | D7: P | E7: -0.01530916 | F7: P | G7: -0.92841677 | H7: O | I7: -1.6748586 | J7: O | K7: -2.1050425 | L7: O
B8: Acumulada tras cláusula de escape de defensa | E8: 0.16057498 | F8: P | G8: -0.63233095 | H8: P | I8: -1.2161628 | J8: O | K8: -1.5046596 | L8: O
B12: Fuente: Informe de Progreso Anual y AIReF

Sheet Cuadro 10
A1: Índice de cuadros
B4: CUADRO 10. GASTO PRIMARIO NETO DE MEDIDAS DE INGRESOS POR SUBSECTORES (% VARIACIÓN)
C6: 2025 | D6: 2026 | E6: 2027 | F6: 2028
B7: AA. PP. | C7: 4.8439715 | D7: 5.8197375 | E7: 5.1804364 | F7: 4.2353121
B8: A. C. | C8: 5.8841269 | D8: 8.9138939 | E8: 4.0398187 | F8: 4.7935471
B9: F. S. S. | C9: 4.7425377 | D9: 4.9863013 | E9: 4.7079701 | F9: 3.8670315
B10: CC. AA. | C10: 4.9375607 | D10: 4.2399382 | E10: 6.407784 | F10: 4.470501
B11: CC. LL. | C11: 2.3553798 | D11: 5.3395468 | E11: 5.8850004 | F11: 3.2192645
B13: Fuente: AIReF

Sheet Cuadro 11
A1: Índice de cuadros
B3: CUADRO 11. COMPARATIVA DE LAS PROYECCIONES DEMOGRÁFICAS DE LA AIREF CON LAS DE OTROS ORGANISMOS PARA DIVERSOS AÑOS
D5: 2025 | E5: 2030 | F5: 2035 | G5: 2040 | H5: 2045 | I5: 2050 | J5: Promedio 2025-2050
B6: Población total (Miles) | C6: INE 2024 | D6: 49265.049 | E6: 51876.064 | F6: 53109.718 | G6: 53892.709 | H6: 54514.658 | I6: 54884.721 | J6: 53103.14
C7: EUROPOP2025 | D7: 49128.297 | E7: 50947.559 | F7: 51977.041 | G7: 52872.036 | H7: 53552.939 | I7: 53877.467 | J7: 52176.991
C8: EUROPOP2023 | D8: 48614.06 | E8: 49266.93 | F8: 49760.92 | G8: 50237.193 | H8: 50527.425 | I8: 50460.161 | J8: 49875.377
C9: AIReF 2026 | D9: 49128.297 | E9: 51394.484 | F9: 52260.348 | G9: 52553.403 | H9: 52709.215 | I9: 52728.898 | J9: 51958.762
C10: AIReF 2025 | D10: 49081.526 | E10: 50119.31 | F10: 50691.139 | G10: 51213.189 | H10: 51705.964 | I10: 52094.597 | J10: 50872.391
B11: Población de 15-74 años (Miles) | C11: INE 2024 | D11: 37885.777 | E11: 40273.627 | F11: 40874.263 | G11: 40478.229 | H11: 39874.037 | I11: 39218.456 | J11: 40019.72
C12: EUROPOP2025 | D12: 37745.287 | E12: 39448.752 | F12: 39954.748 | G12: 39707.553 | H12: 39125.215 | I12: 38321.532 | J12: 39259.524
C13: EUROPOP2023 | D13: 37204.985 | E13: 37878.077 | F13: 37799.883 | G13: 37094.416 | H13: 36131.751 | I13: 34998.546 | J13: 37009.577
C14: AIReF 2026 | D14: 37745.287 | E14: 39782.755 | F14: 40183.979 | G14: 39635.958 | H14: 38831.011 | I14: 37966.416 | J14: 39249.957
C15: AIReF 2025 | D15: 37697.449 | E15: 38669.71 | F15: 38722.54 | G15: 38168.376 | H15: 37435.644 | I15: 36718.645 | J15: 38048.813
B16: Número de hijos por mujer | C16: INE 2024 | D16: 1.1329042 | E16: 1.1663795 | F16: 1.2096138 | G16: 1.2560737 | H16: 1.2788302 | I16: 1.2869753 | J16: 1.2244052
C17: EUROPOP2025 | D17: 1.10738 | E17: 1.13097 | F17: 1.15201 | G17: 1.17322 | H17: 1.19445 | I17: 1.21568 | J17: 1.1625996
C18: AIReF 2026 | D18: 1.1036938 | E18: 1.0890768 | F18: 1.0542644 | G18: 1.03337 | H18: 1.0246367 | I18: 1.0166261 | J18: 1.0522255
C19: AIReF 2025 | D19: 1.1276932 | E19: 1.1747067 | F19: 1.2078317 | G19: 1.2432503 | H19: 1.2764137 | I19: 1.3061325 | J19: 1.2246568
B20: Esperanza de vida al nacer (Años) | C20: INE 2024 | D20: 83.652743 | E20: 84.347329 | F20: 84.996714 | G20: 85.594531 | H20: 86.132068 | I20: 86.597376 | J20: 85.239652
C21: EUROPOP2025 | D21: 84.099183 | E21: 84.554876 | F21: 85.106855 | G21: 85.558932 | H21: 86.010728 | I21: 86.562169 | J21: 85.301786
C22: AIReF 2026 | D22: 84.098444 | E22: 84.7803 | F22: 85.36922 | G22: 85.940646 | H22: 86.495735 | I22: 87.035478 | J22: 85.633685
C23: AIReF 2025 | D23: 84.05097 | E23: 84.68061 | F23: 85.288365 | G23: 85.861487 | H23: 86.420643 | I23: 86.963127 | J23: 85.551666
B24: Esperanza de vida a los 65 años (Años) | C24: INE 2024 | D24: 21.547168 | E24: 22.007649 | F24: 22.443159 | G24: 22.846247 | H24: 23.212497 | I24: 23.531349 | J24: 22.610234
C25: EUROPOP2025 | D25: 22.041302 | E25: 22.370957 | F25: 22.758689 | G25: 23.093621 | H25: 23.489 | I25: 23.839705 | J25: 22.928439
C26: AIReF 2026 | D26: 22.033417 | E26: 22.531295 | F26: 22.950454 | G26: 23.371025 | H26: 23.809939 | I26: 24.240248 | J26: 23.16219
C27: AIReF 2025 | D27: 21.996125 | E27: 22.445602 | F27: 22.879256 | G27: 23.301172 | H27: 23.743923 | I27: 24.177556 | J27: 23.091284
B28: Inmigración neta (Miles) | C28: INE 2024 | D28: 775.19801 | E28: 446.78101 | F28: 294.67101 | G28: 280.089 | H28: 284.022 | I28: 286.422 | J28: 369.89897
C29: EUROPOP2025 | D29: 568.24 | E29: 368.487 | F29: 332.095 | G29: 329.129 | H29: 311.887 | I29: 290.95 | J29: 354.35858
C30: AIReF 2026 | D30: 552.49623 | E30: 399.54124 | F30: 233.789 | G30: 234.23498 | H30: 250.23077 | I30: 269.12241 | J30: 320.87808
C31: AIReF 2025 | D31: 399.15038 | E31: 249.81616 | F31: 236.83648 | G31: 245.95164 | H31: 258.45295 | I31: 271.56683 | J31: 263.84942
B33: Fuente: | C33: INE, Eurostat y AIReF

Sheet Cuadro 12
A1: Índice de cuadros
B3: CUADRO 12. EMPLEOS NO FINANCIEROS SIN PRTR (% PIB)
D5: 2025 | E5: 2030 | F5: 2050 | H5: 2025-2030 | I5: 2030-2050
B6: Empleos no Financieros | D6: 44.5245 | E6: 45.688101 | F6: 51.574935 | H6: =E6-D6 -> 1.1636009 | I6: =F6-E6 -> 5.8868334
B7: Modelizados | D7: 28.07566 | E7: 29.032812 | F7: 34.920104 | H7: =E7-D7 -> 0.95715286 | I7: =F7-E7 -> 5.8872911
B8: Pensiones | D8: 12.953716 | E8: 13.519808 | F8: 16.398787 | H8: =E8-D8 -> 0.56609163 | I8: =F8-E8 -> 2.8789794
B9: Intereses | D9: 2.3894705 | E9: 2.8062749 | F9: 4.4105118 | H9: =E9-D9 -> 0.41680438 | I9: =F9-E9 -> 1.6042368
B10: Sanidad | D10: 6.471819 | E10: 6.5642222 | F10: 7.9394281 | H10: =E10-D10 -> 0.092403195 | I10: =F10-E10 -> 1.3752059
B11: Cuidados larga duración | D11: 0.82996582 | E11: 0.9463415 | F11: 1.5624242 | H11: =E11-D11 -> 0.11637568 | I11: =F11-E11 -> 0.61608269
B12: Educación | D12: 3.9823301 | E12: 3.9538204 | F12: 3.3263002 | H12: =E12-D12 -> -0.028509742 | I12: =F12-E12 -> -0.62752015
B13: Desempleo | D13: 1.4483579 | E13: 1.2423457 | F13: 1.2826522 | H13: =E13-D13 -> -0.20601227 | I13: =F13-E13 -> 0.040306481
B14: No modelizados | D14: 16.448841 | E14: 16.655289 | F14: 16.654831 | H14: =E14-D14 -> 0.20644806 | I14: =F14-E14 -> -0.00045762153

Sheet Anexo I. Cuadro 1
A1: Índice de cuadros
B3: ANEXO I. CUADRO 1. ESTRUCTURA PORCENTUAL DE LA POBLACIÓN SEGÚN TRAMOS ETARIOS
D5: 2002 | E5: 2008 | F5: 2025 | G5: 2030 | H5: 2040 | I5: 2050
B6: Tramos de Edad | C6: De 0 a 14 años | D6: 0.14507122 | E6: 0.14632199 | F6: 0.12913256 | G6: 0.11573179 | H6: 0.10469117 | I6: 0.10388804
C7: De 15 a 74 años | D7: 0.78091684 | E7: 0.77148418 | F7: 0.76830033 | G7: 0.77406663 | H7: 0.75420345 | I7: 0.72003052
C8: De 75 a 100 o más años | D8: 0.074011964 | E8: 0.082193766 | F8: 0.1025671 | G8: 0.11020158 | H8: 0.14110538 | I8: 0.17608144
B10: Fuente: | C10: INE y AIReF

Sheet Gráfico 1
A1: Índice de gráficos
B3: GRÁFICO 1. GASTO BRUTO PÚBLICO EN PENSIONES (% PIB)
C6: 2015 | D6: =C6+1 -> 2016 | E6: =D6+1 -> 2017 | F6: =E6+1 -> 2018 | G6: =F6+1 -> 2019 | H6: =G6+1 -> 2020 | I6: =H6+1 -> 2021 | J6: =I6+1 -> 2022 | K6: =J6+1 -> 2023 | ... AL6: =AK6+1 -> 2050
B7: Histórico | C7: 12.046519 | D7: 12.019989 | E7: 11.896469 | F7: 12.022447 | G7: 12.246009 | H7: 14.018142 | I7: 13.412342 | J7: =+J8 -> 12.638754 | K7: =+K8 -> 12.836698 | L7: =+L8 -> 12.92885 | M7: 12.953716
B8: Histórico | J8: 12.638754 | K8: 12.836698 | L8: 12.92885 | M8: 12.952132 | N8: 13.00615 | O8: 13.111129 | P8: 13.202549 | Q8: 13.329442 | R8: 13.494434 | S8: 13.692483 | T8: 13.918135 | U8: 14.140943 | V8: 14.353598 | W8: 14.549267 | X8: 14.725665 | Y8: 14.881369 | Z8: 15.0263 | AA8: 15.156005 | AB8: 15.261924 | AC8: 15.38985 | AD8: 15.526495 | AE8: 15.668027 | AF8: 15.807338 | AG8: 15.936301 | AH8: 16.050974 | AI8: 16.14051 | AJ8: 16.20188 | AK8: 16.247217 | AL8: 16.273844
B9: AR 2024 actualizado | M9: =M8 -> 12.952132 | N9: =N8 -> 13.00615 | O9: =O8 -> 13.111129 | P9: =P8 -> 13.202549 | Q9: =Q8 -> 13.329442 | R9: =R8 -> 13.494434 | S9: =S8 -> 13.692483 | T9: =T8 -> 13.918135 | ... AL9: =AL8 -> 16.273844
B10: AIReF 2026 | M10: 12.953716 | N10: 13.054792 | O10: 13.254478 | P10: 13.343227 | Q10: 13.419087 | R10: 13.519808 | S10: 13.596648 | T10: 13.701217 | U10: 13.831612 | V10: 14.003178 | W10: 14.199524 | X10: 14.400431 | Y10: 14.60412 | Z10: 14.810245 | AA10: 15.022807 | AB10: 15.236914 | AC10: 15.440385 | AD10: 15.636377 | AE10: 15.805875 | AF10: 15.957269 | AG10: 16.089828 | AH10: 16.197861 | AI10: 16.285446 | AJ10: 16.347253 | AK10: 16.384862 | AL10: 16.398787

Sheet Gráfico 2
A1: Índice de gráficos
B3: GRÁFICO 2. DEUDA PÚBLICA (%PIB)
C5: Deuda Pública
B6: 1995 | C6: 61.586474
B7: 1996 | C7: 65.441953
B8: 1997 | C8: 64.286299
B9: 1998 | C9: 62.354666
B10: 1999 | C10: 60.853144
B11: 2000 | C11: 57.840514
B12: 2001 | C12: 54.052229
B13: 2002 | C13: 51.236868
B14: 2003 | C14: 47.686949
B15: 2004 | C15: 45.332696
B16: 2005 | C16: 42.395191
B17: 2006 | C17: 39.019058
... B23: 2012 | C23: 89.560379
B24: 2013 | C24: 100.01494 | F24: Fuente: | G24: AIReF
B25: 2014 | C25: 104.44838
B26: 2015 | C26: 102.48521
B27: 2016 | C27: 102.02036
B28: 2017 | C28: 101.20718
B29: 2018 | C29: 99.790955
B30: 2019 | C30: 97.659249
B31: 2020 | C31: 119.27911
B32: 2021 | C32: 115.69678
B33: 2022 | C33: 109.32085
B34: 2023 | C34: 105.18212
B35: 2024 | C35: 101.64604
B36: 2025 | C36: 100.65629
... B61: 2050 | C61: 123.34752

Sheet Gráfico 3
A1: Índice de gráficos
B3: GRÁFICO 3. SALDO PÚBLICO (% PIB)
C6: Saldo primario | D6: Saldo total
B7: 1995 | C7: -1.8526525 | D7: -6.793349
B8: 1996 | C8: -0.8346525 | D8: -5.8658829
B9: 1997 | C9: 0.67730181 | D9: -3.8591752
B10: 1998 | C10: 1.4390911 | D10: -2.6269037
B11: 1999 | C11: 2.1713858 | D11: -1.2401679
B12: 2000 | C12: 2.0021033 | D12: -1.1612662
B13: 2001 | C13: 2.5145586 | D13: -0.4549488
B14: 2002 | C14: 2.3149235 | D14: -0.31424059
B15: 2003 | C15: 1.9247947 | D15: -0.37486779
B16: 2004 | C16: 1.8792897 | D16: -0.1094111
B17: 2005 | C17: 2.9761174 | D17: 1.2305494
B18: 2006 | C18: 3.7304373 | D18: 2.1216427
... B21: 2009 | C21: -9.526743 | D21: -11.237383
B22: 2010 | C22: -7.5900645 | D22: -9.4873949 | G22: Fuente: | H22: AIReF
B23: 2011 | C23: -7.2062993 | D23: -9.6917722
B24: 2012 | C24: -8.4695028 | D24: -11.495959
B25: 2013 | C25: -3.924528 | D25: -7.4884074
B26: 2014 | C26: -2.5034915 | D26: -6.0364849
B27: 2015 | C27: -2.1966458 | D27: -5.2660627
B28: 2016 | C28: -1.4403807 | D28: -4.2210501
B29: 2017 | C29: -0.53759581 | D29: -3.0685695
B30: 2018 | C30: -0.11136078 | D30: -2.5524715
B31: 2019 | C31: -0.81286741 | D31: -3.0646641
B32: 2020 | C32: -7.6841059 | D32: -9.909282
B33: 2021 | C33: -4.5329971 | D33: -6.6512124
B34: 2022 | C34: -2.2771163 | D34: -4.5865758
... B62: 2050 | C62: -2.1465477 | D62: -6.5427269

Sheet Gráfico 4
A1: Índice de gráficos
B3: GRÁFICO 4. EVOLUCIÓN DEL GASTO EN PENSIONES (% PIB)
C6: 2015 | D6: =C6+1 -> 2016 | E6: =D6+1 -> 2017 | F6: =E6+1 -> 2018 | G6: =F6+1 -> 2019 | H6: =G6+1 -> 2020 | I6: =H6+1 -> 2021 | J6: =I6+1 -> 2022 | K6: =J6+1 -> 2023 | ... AL6: =AK6+1 -> 2050
B7: Histórico | C7: 12.046519 | D7: 12.019989 | E7: 11.896469 | F7: 12.022447 | G7: 12.246009 | H7: 14.018142 | I7: 13.412342 | J7: =+J8 -> 12.638754 | K7: =+K8 -> 12.836698 | L7: =+L8 -> 12.92885 | M7: 12.953716
B8: Histórico | J8: 12.638754 | K8: 12.836698 | L8: 12.92885 | M8: 12.952132 | N8: 13.00615 | O8: 13.111129 | P8: 13.202549 | Q8: 13.329442 | R8: 13.494434 | S8: 13.692483 | T8: 13.918135 | U8: 14.140943 | V8: 14.353598 | W8: 14.549267 | X8: 14.725665 | Y8: 14.881369 | Z8: 15.0263 | AA8: 15.156005 | AB8: 15.261924 | AC8: 15.38985 | AD8: 15.526495 | AE8: 15.668027 | AF8: 15.807338 | AG8: 15.936301 | AH8: 16.050974 | AI8: 16.14051 | AJ8: 16.20188 | AK8: 16.247217 | AL8: 16.273844 | AN8: =AVERAGE(J8:AL8) -> 14.567182
B9: AR 2024 actualizado | M9: =M8 -> 12.952132 | N9: =N8 -> 13.00615 | O9: =O8 -> 13.111129 | P9: =P8 -> 13.202549 | Q9: =Q8 -> 13.329442 | R9: =R8 -> 13.494434 | S9: =S8 -> 13.692483 | T9: =T8 -> 13.918135 | ... AL9: =AL8 -> 16.273844
B10: Opinión 2025 | M10: 12.994066 | N10: 13.075227 | O10: 13.150043 | P10: 13.209202 | Q10: 13.272752 | R10: 13.38896 | S10: 13.520017 | T10: 13.664946 | U10: 13.834009 | V10: 14.009667 | W10: 14.193417 | X10: 14.382237 | Y10: 14.571124 | Z10: 14.767681 | AA10: 14.967077 | AB10: 15.158819 | AC10: 15.34264 | AD10: 15.515272 | AE10: 15.672087 | AF10: 15.811336 | AG10: 15.928084 | AH10: 16.020618 | AI10: 16.08662 | AJ10: 16.125515 | AK10: 16.140297 | AL10: 16.128704
B11: AIReF 2026 | M11: 12.953716 | N11: 13.054792 | O11: 13.254478 | P11: 13.343227 | Q11: 13.419087 | R11: 13.519808 | S11: 13.596648 | T11: 13.701217 | U11: 13.831612 | V11: 14.003178 | W11: 14.199524 | X11: 14.400431 | Y11: 14.60412 | Z11: 14.810245 | AA11: 15.022807 | AB11: 15.236914 | AC11: 15.440385 | AD11: 15.636377 | AE11: 15.805875 | AF11: 15.957269 | AG11: 16.089828 | AH11: 16.197861 | AI11: 16.285446 | AJ11: 16.347253 | AK11: 16.384862 | AL11: 16.398787
B12: AIReF + Población EUROPOP2025 | M12: =M11 -> 12.953716 | N12: =N11 -> 13.054792 | O12: =O11 -> 13.254478 | P12: =P11 -> 13.343227 | Q12: =Q11 -> 13.419087 | R12: =R11 -> 13.519808 | S12: 13.539784 | T12: 13.64287 | U12: 13.766345 | V12: 13.927143 | W12: 14.110997 | X12: 14.299807 | Y12: 14.492993 | Z12: 14.690922 | AA12: 14.897431 | AB12: 15.105875 | AC12: 15.304544 | AD12: 15.4983 | AE12: 15.668869 | AF12: 15.824351 | AG12: 15.963354 | AH12: 16.080247 | AI12: 16.178204 | AJ12: 16.252364 | AK12: 16.304465 | AL12: 16.334875

Sheet Gráfico 5
A1: Índice de gráficos
B3: GRÁFICO 5. DESCOMPOSICIÓN DEL CRECIMIENTO DEL GASTO EN PENSIONES
C6: 2025-2030 | D6: 2031-2035 | E6: 2036-2040 | F6: 2041-2045 | G6: 2046-2050 | H6: 2051-2055 | I6: 2056-2060 | J6: 2061-2065 | K6: 2066-2070
B7: Revalorización | C7: 0.025017061 | D7: 0.02 | E7: 0.02 | F7: 0.02 | G7: 0.02 | H7: 0.02 | I7: 0.02 | J7: 0.02 | K7: 0.02
B8: Número pensiones | C8: 0.018589173 | D8: 0.020749796 | E8: 0.020595156 | F8: 0.017412354 | G8: 0.011080865 | H8: 0.0047329049 | I8: 0.00077221784 | J8: -0.0011290226 | K8: -0.00068784577
B9: Efecto sustitución | C9: 0.0072822813 | D9: 0.0034676376 | E9: 0.0037874452 | F9: 0.0040261984 | G9: 0.0035851249 | H9: 0.0046779732 | I9: 0.0065773764 | J9: 0.0082753946 | K9: 0.0094821032
B10: Medidas | C10: 0.0041575076
B11: TOTAL | C11: =SUM(C7:C10) -> 0.055046023 | D11: =SUM(D7:D10) -> 0.044217433 | E11: =SUM(E7:E10) -> 0.044382601 | F11: =SUM(F7:F10) -> 0.041438553 | G11: =SUM(G7:G10) -> 0.034665989 | H11: =SUM(H7:H10) -> 0.029410878 | I11: =SUM(I7:I10) -> 0.027349594 | J11: =SUM(J7:J10) -> 0.027146372 | K11: =SUM(K7:K10) -> 0.028794257

Sheet Gráfico 6
A1: Índice de gráficos
B3: GRÁFICO 6. NÚMERO DE PENSIONES (MILLONES)
B5: %PIB | C5: 2025 | D5: 2030 | E5: 2035 | F5: 2040 | G5: 2045 | H5: 2050 | I5: 2055 | J5: 2060 | K5: 2065 | L5: 2070
B6: Seguridad Social | C6: 10.465964 | D6: 11.497554 | E6: 12.740954 | F6: 14.108128 | G6: 15.379862 | H6: 16.250902 | I6: 16.63904 | J6: 16.703351 | K6: 16.60927 | L6: 16.552217
B7: Clases Pasivas | C7: 0.72434517 | D7: 0.78378069 | E7: 0.80619622 | F7: 0.81640001 | G7: 0.79328719 | H7: 0.71243836 | I7: 0.59296495 | J7: 0.46741554 | K7: 0.35187657 | L7: 0.24319569
B8: Pensiones no contributivas | C8: 0.446119 | D8: 0.446119 | E8: 0.446119 | F8: 0.446119 | G8: 0.446119 | H8: 0.446119 | I8: 0.446119 | J8: 0.446119 | K8: 0.446119 | L8: 0.446119
B9: TOTAL | C9: =+C6+C7+C8 -> 11.636428 | D9: =+D6+D7+D8 -> 12.727453 | E9: =+E6+E7+E8 -> 13.993269 | F9: =+F6+F7+F8 -> 15.370647 | G9: =+G6+G7+G8 -> 16.619268 | H9: =+H6+H7+H8 -> 17.409459 | I9: =+I6+I7+I8 -> 17.678124 | J9: =+J6+J7+J8 -> 17.616886 | ... L9: =+L6+L7+L8 -> 17.241532

Sheet Gráfico 7
A1: Índice de gráficos
B3: GRÁFICO 7. TASA DE GENEROSIDAD (PENSIÓN MEDIA/SALARIO MEDIO)
C5: 2015 | D5: 2016 | E5: 2017 | F5: 2018 | G5: 2019 | H5: 2020 | I5: 2021 | J5: 2022 | K5: =J5+1 -> 2023 | L5: =K5+1 -> 2024 | M5: =L5+1 -> 2025 | N5: =M5+1 -> 2026 | O5: =N5+1 -> 2027 | P5: =O5+1 -> 2028 | Q5: =P5+1 -> 2029 | R5: =Q5+1 -> 2030 | ... BF5: =BE5+1 -> 2070
B6: Histórico | C6: 57.048702 | D6: 58.359414 | E6: 59.396877 | F6: 61.076121 | G6: 62.120227 | H6: 65.296382 | I6: 62.806077 | J6: 63.562997 | K6: 66.424094 | L6: 66.927519 | M6: 68.388093
B7: Opinión 2025 | K7: 65.614178 | L7: 65.455195 | M7: 66.36563 | N7: 66.774188 | O7: 66.881965 | P7: 66.984031 | Q7: 67.102167 | R7: 66.758824 | S7: 66.384857 | T7: 65.985611 | U7: 65.515583 | V7: 65.030192 | W7: 64.526633 | X7: 64.015243 | Y7: 63.501733 | Z7: 62.983462 | AA7: 62.452063 | AB7: 61.933325 | AC7: 61.411103 | AD7: 60.888421 | AE7: 60.353428 | AF7: 59.814127 | AG7: 59.275137 | AH7: 58.737826 | AI7: 58.208277 | AJ7: 57.689264 | AK7: 57.183102 | AL7: 56.695891 | AM7: 56.235775 | AN7: 55.813956 | AO7: 55.424607 | AP7: 55.07686 | AQ7: 54.761063 | AR7: 54.481502 | AS7: 54.233869 | AT7: 54.020392 | AU7: 53.835516 | AV7: 53.684994 | AW7: 53.565362 | AX7: 53.476141 | AY7: 53.416965 | AZ7: 53.388178 | BA7: 53.38569 | BB7: 53.407883 | BC7: 53.455438 | BD7: 53.530726 | BE7: 53.627895 | BF7: 53.744424
B8: AIReF 2026 | M8: 68.388093 | N8: 69.043999 | O8: 69.954661 | P8: 70.331816 | Q8: 70.402335 | R8: 70.539068 | S8: 69.975783 | T8: 69.376087 | U8: 68.744737 | V8: 68.316652 | W8: 67.830841 | X8: 67.339312 | Y8: 66.845035 | Z8: 66.362739 | AA8: 65.861767 | AB8: 65.354461 | AC8: 64.851195 | AD8: 64.341752 | AE8: 63.839358 | AF8: 63.327393 | AG8: 62.80463 | AH8: 62.277198 | AI8: 61.739184 | AJ8: 61.204541 | AK8: 60.68111 | AL8: 60.170599 | AM8: 59.687799 | AN8: 59.2371 | AO8: 58.827649 | AP8: 58.46529 | AQ8: 58.151943 | AR8: 57.878452 | AS8: 57.645331 | AT8: 57.445502 | AU8: 57.273231 | AV8: 57.13374 | AW8: 57.020922 | AX8: 56.931055 | AY8: 56.867006 | AZ8: 56.82464 | BA8: 56.808093 | BB8: 56.817477 | BC8: 56.8512 | BD8: 56.912658 | BE8: 57.000063 | BF8: 57.112685

Sheet Gráfico 8A
A1: Índice de gráficos
B2: GRÁFICO 8. PROYECCIONES DE PIB NOMINAL Y POBLACIÓN DEL AR2023 FRENTE A ACTUALES
B3: GRÁFICO 8A. PROYECCIONES DE PIB NOMINAL (MILES DE MILLONES DE EUROS)
C6: PIB AR2024 | D6: PIB AR2024 Actualizado | E6: PIB AIReF
B7: 2022 | C7: 1327108 | D7: 1375863 | E7: 1375863
B8: =+B7+1 -> 2023 | C8: 1412901.8 | D8: 1497761 | E8: 1497761
B9: =+B8+1 -> 2024 | C9: 1482982.2 | D9: 1594330 | E9: 1594330
B10: =+B9+1 -> 2025 | C10: 1545902 | D10: 1687152 | E10: 1687152
B11: =+B10+1 -> 2026 | C11: 1604572.7 | D11: 1751183.5 | E11: 1767851.4
B12: =+B11+1 -> 2027 | C12: 1658500.7 | D12: 1810039 | E12: 1849590.3
B13: =+B12+1 -> 2028 | C13: 1709511.5 | D13: 1865710.6 | E13: 1927977.6
B14: =+B13+1 -> 2029 | C14: 1760204.7 | D14: 1921035.7 | E14: 2003000.2
B15: =+B14+1 -> 2030 | C15: 1810531.2 | D15: 1975960.5 | E15: 2079175.6
G20: Fuente: | H20: INE, Eurostat y AIReF

Sheet Gráfico 8B
A1: Índice de gráficos
B2: GRÁFICO 8. PROYECCIONES DE PIB NOMINAL Y POBLACIÓN DEL AR2023 FRENTE A ACTUALES
B3: GRÁFICO 8B. PROYECCIONES DE POBLACIÓN (MILES DE RESIDENTES)
C6: EUROPOP2025 | D6: EUROPOP2023 | E6: AIReF 2026
B7: 2022 | C7: 47486.727 | D7: 47432.893 | E7: 47486.727
B8: =+B7+1 -> 2023 | C8: 48085.361 | D8: 47980.384 | E8: 48085.361
B9: =+B8+1 -> 2024 | C9: 48619.695 | D9: 48346.319 | E9: 48619.695
B10: =+B9+1 -> 2025 | C10: 49128.297 | D10: 48614.06 | E10: 49128.297
B11: =+B10+1 -> 2026 | C11: 49570.728 | D11: 48822.977 | E11: 49570.436
B12: =+B11+1 -> 2027 | C12: 49976.787 | D12: 48973.279 | E12: 50055.838
B13: =+B12+1 -> 2028 | C13: 50341.56 | D13: 49069.647 | E13: 50548.751
B14: =+B13+1 -> 2029 | C14: 50665.174 | D14: 49167.929 | E14: 51021.979
B15: =+B14+1 -> 2030 | C15: 50947.559 | D15: 49266.93 | E15: 51394.484
G20: Fuente: | H20: INE, Eurostat y AIReF

Sheet Gráfico 9
A1: Índice de gráficos
B3: GRÁFICO 9. INCIDENCIA DEL SMI (PORCENTAJE DE TRABAJADORES SOBRE TOTAL DE AFILIADOS AL RÉGIMEN GENERAL), 2018-2024
C5: Hasta el 100% del SMI | D5: hasta el 125% del SMI
B6: 2018 | C6: 0.030994667 | D6: 0.081908548
B7: 2019 | C7: 0.059527004 | D7: 0.19215197
B8: 2020 | C8: 0.06828052 | D8: 0.21391866
B9: 2021 | C9: 0.065684639 | D9: 0.21287178
B10: 2022 | C10: 0.066104887 | D10: 0.22752121
B11: 2023 | C11: 0.080186604 | D11: 0.25698935
B12: 2024 | C12: 0.091867206 | D12: 0.27072389
H24: Fuente: | I24: AIReF, a partir de la MCVL
H25: Nota: Incidencia calculada como media anual ponderada por personas-mes. Bases de cotización elevadas a jornada y mes completos a nivel episodio-personames. Se excluyen meses-persona coincidentes con prestación o suspensión temporal de empleo. Los niveles difieren ligeramente respecto al DT 9/25 por la mayor desagregación del panel y la depuración de prestaciones. Se han eliminado de la muestra las bases de cotización que superan la base máxima.

Sheet Gráfico 10
A1: Índice de gráficos
B3: GRÁFICO 10. DISTRIBUCIÓN DE LAS BASES DE COTIZACIÓN MENSUALES, 2018, 2023 Y 2024
C6: 2018 | D6: 2023 | E6: 2024
B7: [750,775) | C7: 0 | D7: 0 | E7: 0
B8: [775,800) | C8: 0 | D8: 0 | E8: 0
B9: [800,825) | C9: 0 | D9: 0 | E9: 0
B10: [825,850) | C10: 0 | D10: 0 | E10: 0
B11: [850,875) | C11: 0.019809072 | D11: 0 | E11: 0
B12: [875,900) | C12: 0.0073265123 | D12: 0 | E12: 0
B13: [900,925) | C13: 0.0073191927 | D13: 0 | E13: 0
B14: [925,950) | C14: 0.0070154293 | D14: 0 | E14: 0
B15: [950,975) | C15: 0.009109648 | D15: 0 | E15: 0
B16: [975,1000) | C16: 0.0089898912 | D16: 0 | E16: 0
B17: [1000,1025) | C17: 0.010064246 | D17: 0 | E17: 0
B18: [1025,1050) | C18: 0.010816538 | D18: 0 | E18: 0
... B28: [1275,1300) | C28: 0.022959957 | D28: 0.021614573 | E28: 0
B29: [1300,1325) | C29: 0.023844408 | D29: 0.031904304 | E29: 0.045928046 | H29: Fuente: | I29: AIReF, a partir de la MCVL
B30: [1325,1350) | C30: 0.02259845 | D30: 0.028209532 | E30: 0.022128775 | H30: Nota: Bases de cotización mensuales elevadas a jornada y mes completos a nivel episodiopersona-mes. Se excluyen los meses-persona en los que el episodio laboral coincide con prestación por desempleo o suspensión temporal de empleo.
B31: [1350,1375) | C31: 0.02314254 | D31: 0.02691803 | E31: 0.02954048
B32: [1375,1400) | C32: 0.022542943 | D32: 0.027484892 | E32: 0.024651597
B33: [1400,1425) | C33: 0.023593915 | D33: 0.024329128 | E33: 0.02988999
B34: [1425,1450) | C34: 0.024272401 | D34: 0.023945663 | E34: 0.025540319
B35: [1450,1475) | C35: 0.022331081 | D35: 0.024557662 | E35: 0.02893214
B36: [1475,1500) | C36: 0.022612276 | D36: 0.022903636 | E36: 0.024277688
B37: [1500,1525) | C37: 0.024416557 | D37: 0.025527509 | E37: 0.026294644
B38: [1525,1550) | C38: 0.022098684 | D38: 0.021507016 | E38: 0.024851463
B39: [1550,1575) | C39: 0.021417554 | D39: 0.021840871 | E39: 0.022569375
B40: [1575,1600) | C40: 0.021514539 | D40: 0.021774588 | E40: 0.022487029
B41: [1600,1625) | C41: 0.020565024 | D41: 0.023298285 | E41: 0.022192212
B42: [1625,1650) | C42: 0.018967725 | D42: 0.022741995 | E42: 0.020837273
... B121: [3600,3625) | C121: 0.0027997467 | D121: 0.0039875551 | E121: 0.0043909463

Sheet Gráfico 11A
A1: Índice de gráficos
B3: GRÁFICO 11. A. TASAS DE TRANSICIÓN ENTRE EMPLEO Y NO EMPLEO SEGÚN DURACIÓN DEL EPISODIO. SALIDA DEL NO EMPLEO AL EMPLEO | G3: TASAS DE TRANSICIÓN ENTRE EMPLEO Y NO EMPLEO SEGÚN DURACIÓN DEL EPISODIO
B6: Meses en desempleo/Inactividad | C6: Periodo 2022-2024 | D6: Periodo 2017-2019
B7: 1 | C7: 0.30236678 | D7: 0.30059372
B8: 2 | C8: 0.27054806 | D8: 0.25349386
B9: 3 | C9: 0.22271511 | D9: 0.20705873
B10: 4 | C10: 0.15822169 | D10: 0.14641678
B11: 5 | C11: 0.12593087 | D11: 0.1154989
B12: 6 | C12: 0.10772762 | D12: 0.10074916
B13: 7 | C13: 0.084505436 | D13: 0.080276388
B14: 8 | C14: 0.067045259 | D14: 0.06251878
B15: 9 | C15: 0.06522782 | D15: 0.06125401
B16: 10 | C16: 0.067417124 | D16: 0.0634241
B17: 11 | C17: 0.063048396 | D17: 0.056948304
B18: 12 | C18: 0.051166398 | D18: 0.047780653
G24: Fuente: | H24: AIReF, a partir de la MCVL
G25: Nota: Tasas calculadas con la MCVL-2025 a partir de ficheros de transiciones actualizados. Los niveles pueden diferir de los gráficos descriptivos del DT 8/25 por la incorporación de la nueva ola y por las mejoras en la reconstrucción de las trayectorias laborales, especialmente en la identificación de episodios consecutivos o solapados, el cálculo de su duración efectiva y la depuración de situaciones compatibles con empleo o prestación.

Sheet Gráfico 11B
A1: Índice de gráficos
B3: GRÁFICO 11. B. TASAS DE TRANSICIÓN ENTRE EMPLEO Y NO EMPLEO SEGÚN DURACIÓN DEL EPISODIO. SALIDA DEL EMPLEO AL NO EMPLEO
B6: Meses en empleo | C6: Periodo 2017-2019 | D6: Periodo 2022-2024
B7: 1 | C7: 0.088409297 | D7: 0.072527031
B8: 2 | C8: 0.10819855 | D8: 0.10124616
B9: 3 | C9: 0.086858093 | D9: 0.075834882
B10: 4 | C10: 0.077390015 | D10: 0.063921412
B11: 5 | C11: 0.050638705 | D11: 0.040444214
B12: 6 | C12: 0.055171047 | D12: 0.044198448
B13: 7 | C13: 0.051855785 | D13: 0.03672895
B14: 8 | C14: 0.036033535 | D14: 0.026299726
B15: 9 | C15: 0.034161842 | D15: 0.025240923
B16: 10 | C16: 0.032908813 | D16: 0.024424168
B17: 11 | C17: 0.025331876 | D17: 0.02023139
B18: 12 | C18: 0.046211894 | D18: 0.029099185
... B22: 16 | C22: 0.010609459 | D22: 0.011519804
B23: 17 | C23: 0.010020991 | D23: 0.010856257 | H23: Fuente: | I23: AIReF, a partir de la MCVL
B24: 18 | C24: 0.010364631 | D24: 0.01094447 | H24: Nota: Tasas calculadas con la MCVL-2025 a partir de ficheros de transiciones actualizados. Los niveles pueden diferir de los gráficos descriptivos del DT 8/25 por la incorporación de la nueva ola y por las mejoras en la reconstrucción de las trayectorias laborales, especialmente en la identificación de episodios consecutivos o solapados, el cálculo de su duración efectiva y la depuración de situaciones compatibles con empleo o prestación.
B25: 19 | C25: 0.010281816 | D25: 0.01021103
B26: 20 | C26: 0.010407033 | D26: 0.010565959
B27: 21 | C27: 0.0085530006 | D27: 0.0091798815
B28: 22 | C28: 0.0099510161 | D28: 0.010270682
B29: 23 | C29: 0.0081950782 | D29: 0.0089155009
B30: 24 | C30: 0.013406234 | D30: 0.01085512
B31: 25 | C31: 0.010984552 | D31: 0.0085096037
B32: 26 | C32: 0.007632157 | D32: 0.0077295519
B33: 27 | C33: 0.0076543229 | D33: 0.0073404449
B34: 28 | C34: 0.0068174047 | D34: 0.0070150062
B35: 29 | C35: 0.0068041621 | D35: 0.0063960239
B36: 30 | C36: 0.0062223348 | D36: 0.0058219002
... B42: 36 | C42: 0.0088129102 | D42: 0.0073730601

Sheet Gráfico RE_2.1.
A1: Índice de gráficos
B3: GRÁFICO RE_2.1. TASA DE PARCIALIDAD POR SEXO Y ORIGEN DE LOS INMIGRANTES (%)
C6: Hombres | D6: Mujeres
B7: ASIA | C7: 4.4480911 | D7: 14.473906
B8: EUROPA | C8: 4.9518406 | D8: 21.781389
B9: AMÉRICA | C9: 9.6416021 | D9: 29.666465
B10: ÁFRICA Y ORIENTE PRÓXIMO | C10: 6.6932471 | D10: 31.800084
H23: Fuente: | I23: AIReF a partir de microdatos EPA
H24: Nota: Porcentaje de ocupados a tiempo parcial sobre el total de ocupados.

Sheet Gráfico RE_2.2.
A1: Índice de gráficos
B3: GRÁFICO RE_2.2. ESTIMACIÓN FLUJOS PERSONAS REGULARIZABLES DA21

Sheet Gráfico RE_2.3.
A1: Índice de gráficos
B3: GRÁFICO RE_2.3. AFILIADOS EXTRANJEROS EN 2005: OBSERVADO VS. CONTRAFACTUAL (MILES)
B6: date | C6: excess
B7: 36526 | C7: 0.19531001
B8: 36557 | C8: 0.094582836
B9: 36586 | C9: 0.070296553
B10: 36617 | C10: 0.064414083
B11: 36647 | C11: 0.067743189
B12: 36678 | C12: 0.068582246
B13: 36708 | C13: 0.069028907
B14: 36739 | C14: 0.065372765
B15: 36770 | C15: 0.074980869
B16: 36800 | C16: 0.075144279
B17: 36831 | C17: 0.080167947
B18: 36861 | C18: -0.13964231
... B21: 36951 | C21: 3.2400268
B22: 36982 | C22: -3.0000776 | E22: Fuente: AIReF
B23: 37012 | C23: 4.7758464
B24: 37043 | C24: 0.13519262
B25: 37073 | C25: -11.767496
B26: 37104 | C26: 1.4263932
B27: 37135 | C27: 4.0799195
B28: 37165 | C28: -0.54389605
B29: 37196 | C29: 1.4290612
B30: 37226 | C30: -2.5241358
B31: 37257 | C31: 6.7409098
B32: 37288 | C32: 4.6987897
B33: 37316 | C33: 4.8093846
B34: 37347 | C34: 14.728478
... B61: 38169 | C61: -5.5321008
B62: 38200 | C62: -0.71878641 | E62: Fuente: AIReF
B63: 38231 | C63: 13.077975
B64: 38261 | C64: 4.9635517
B65: 38292 | C65: -11.629424
B66: 38322 | C66: 4.3205173
B67: 38353 | C67: -1.9350255
B68: 38384 | C68: 3.1232337
B69: 38412 | C69: 52.839895
B70: 38443 | C70: 121.51748
B71: 38473 | C71: 165.31255
...

Sheet Gráfico RE_2.4.
A1: Índice de gráficos
B3: GRÁFICO RE_2.4. BASE MEDIA ANUAL DE COTIZACIÓN DE INMIGRANTES (MILES DE EUROS)
C6: Año 1 | D6: Año 2 | E6: Año 3
B7: Base | C7: 7.23 | D7: 12.31 | E7: 12.38
B8: Rango perfiles demográficos | C8: 3.26 | D8: 4.43 | E8: 6.6
B9: Media ponderada | C9: 8.5982939 | D9: 14.022461 | E9: 13.85721
H26: Fuente: AIReF, a partir de la MCVL-2025

Sheet Gráfico RE_2.5.
A1: Índice de gráficos
B3: GRÁFICO RE_2.5. DISTRIBUCIÓN DEL IMPACTO POTENCIAL DE COTIZACIONES (% PIB) CON DISTINTAS COMBINACIONES DE PARÁMETROS PARA EL PRIMER AÑO19

Sheet Gráfico 12
A1: Índice de gráficos
B3: GRÁFICO 12. FUENTES DE FINANCIACIÓN DEL SISTEMA PÚBLICO DE PENSIONES
D5: Rúbrica | E5: 2020 | F5: =+E5+1 -> 2021 | G5: =+F5+1 -> 2022 | H5: =+G5+1 -> 2023 | I5: =+H5+1 -> 2024 | J5: =+I5+1 -> 2025 | K5: =+J5+1 -> 2026 | L5: =+K5+1 -> 2027 | M5: =+L5+1 -> 2028 | ... BC5: =+BB5+1 -> 2070
B6: Pensiones CPE | C6: Ingreso | D6: Presupuesto del Estado | E6: 1.4646317 | F6: 1.3998675 | G6: 1.3512956 | H6: 1.3928761 | I6: 1.4018938 | J6: 1.3899685 | K6: 1.3967331 | L6: 1.4227349 | M6: 1.4352773 | N6: 1.4385958 | O6: 1.4337258 | P6: 1.4269953 | Q6: 1.4229951 | R6: 1.418984 | S6: 1.417409 | T6: 1.4162515 | U6: 1.4152825 | V6: 1.4145379 | W6: 1.4143539 | X6: 1.4135486 | Y6: 1.4111346 | Z6: 1.4070181 | AA6: 1.3998471 | AB6: 1.3872387 | AC6: 1.3695865 | AD6: 1.3481533 | AE6: 1.3216609 | AF6: 1.2913651 | AG6: 1.2564402 | AH6: 1.2180146 | AI6: 1.1754815 | AJ6: 1.1296479 | AK6: 1.0822855 | AL6: 1.0336789 | AM6: 0.9844413 | AN6: 0.93409571 | AO6: 0.88344461 | AP6: 0.83340464 | AQ6: 0.7848229 | AR6: 0.73781618 | AS6: 0.69282286 | AT6: 0.64929431 | AU6: 0.60737462 | AV6: 0.56693679 | AW6: 0.52803417 | AX6: 0.49107154 | AY6: 0.45476305 | AZ6: 0.41884081 | BA6: 0.38434649 | BB6: 0.35101577 | BC6: 0.31920127
C7: Gasto | D7: Prestaciones en efectivo AC | E7: 1.4646317 | F7: 1.3998675 | G7: 1.3512956 | H7: 1.3928761 | I7: 1.4018938 | J7: 1.3899685 | K7: 1.3967331 | L7: 1.4227349 | M7: 1.4352773 | N7: 1.4385958 | O7: 1.4337258 | P7: 1.4269953 | Q7: 1.4229951 | R7: 1.418984 | S7: 1.417409 | T7: 1.4162515 | U7: 1.4152825 | V7: 1.4145379 | W7: 1.4143539 | X7: 1.4135486 | Y7: 1.4111346 | Z7: 1.4070181 | AA7: 1.3998471 | AB7: 1.3872387 | AC7: 1.3695865 | AD7: 1.3481533 | AE7: 1.3216609 | AF7: 1.2913651 | AG7: 1.2564402 | AH7: 1.2180146 | AI7: 1.1754815 | AJ7: 1.1296479 | AK7: 1.0822855 | AL7: 1.0336789 | AM7: 0.9844413 | AN7: 0.93409571 | AO7: 0.88344461 | AP7: 0.83340464 | AQ7: 0.7848229 | AR7: 0.73781618 | AS7: 0.69282286 | AT7: 0.64929431 | AU7: 0.60737462 | AV7: 0.56693679 | AW7: 0.52803417 | AX7: 0.49107154 | AY7: 0.45476305 | AZ7: 0.41884081 | BA7: 0.38434649 | BB7: 0.35101577 | BC7: 0.31920127
D8: Saldo | E8: =+E6-E7 -> 0 | F8: =+F6-F7 -> 0 | G8: =+G6-G7 -> 0 | H8: =+H6-H7 -> 0 | I8: =+I6-I7 -> 0 | J8: =+J6-J7 -> 0 | K8: =+K6-K7 -> 0 | L8: =+L6-L7 -> 0 | ... BC8: =+BC6-BC7 -> 0
B9: Pensiones contributivas | C9: Ingreso | D9: Cotizaciones SSS dedicadas a pensiones | E9: 9.1977835 | F9: 9.2034777 | G9: 9.0448684 | H9: 9.2477131 | I9: 9.4876331 | J9: 9.6157574 | K9: 9.7046109 | L9: 9.8572704 | M9: 9.8819584 | N9: 9.9204971 | O9: 9.9262247 | P9: 10.062006 | Q9: 10.19443 | R9: 10.217476 | S9: 10.239645 | T9: 10.261624 | U9: 10.281157 | V9: 10.299946 | W9: 10.31802 | X9: 10.33578 | Y9: 10.35308 | Z9: 10.369896 | AA9: 10.386239 | AB9: 10.401532 | AC9: 10.416415 | AD9: 10.431141 | AE9: 10.44078 | AF9: 10.450117 | AG9: 10.459027 | AH9: 10.467371 | AI9: 10.475131 | AJ9: 10.465171 | AK9: 10.455623 | AL9: 10.446797 | AM9: 10.438016 | AN9: 10.42981 | AO9: 10.422043 | AP9: 10.41449 | AQ9: 10.40775 | AR9: 10.401647 | AS9: 10.395993 | AT9: 10.391221 | AU9: 10.38714 | AV9: 10.383495 | AW9: 10.380675 | AX9: 10.378173 | AY9: 10.376399 | AZ9: 10.375122 | BA9: 10.373982 | BB9: 10.373406 | BC9: 10.37318
C10: Ingreso | D10: Transferencias de AC | E10: 0.87487453 | F10: 1.6973494 | G10: 1.583694 | H10: 1.5538112 | I10: 1.6021737 | J10: 1.6729481 | K10: 1.6762143 | L10: 1.7049569 | M10: 1.7048885 | N10: 1.7048281 | O10: 1.7047712 | P10: 1.7047712 | Q10: 1.7047712 | R10: 1.7047712 | S10: 1.7047712 | T10: 1.7047712 | U10: 1.7047712 | V10: 1.7047712 | W10: 1.7047712 | X10: 1.7047712 | Y10: 1.7047712 | Z10: 1.7047712 | AA10: 1.7047712 | AB10: 1.7047712 | AC10: 1.7047712 | AD10: 1.7047712 | AE10: 1.7047712 | AF10: 1.7047712 | AG10: 1.7047712 | AH10: 1.7047712 | AI10: 1.7047712 | AJ10: 1.7047712 | AK10: 1.7047712 | AL10: 1.7047712 | AM10: 1.7047712 | AN10: 1.7047712 | AO10: 1.7047712 | AP10: 1.7047712 | AQ10: 1.7047712 | AR10: 1.7047712 | AS10: 1.7047712 | AT10: 1.7047712 | AU10: 1.7047712 | AV10: 1.7047712 | AW10: 1.7047712 | AX10: 1.7047712 | AY10: 1.7047712 | AZ10: 1.7047712 | BA10: 1.7047712 | BB10: 1.7047712 | BC10: 1.7047712
C12: Gasto | D12: Pensiones SS + complemento a mínimos | E12: 12.325973 | F12: 11.802027 | G12: 11.1183 | H12: 11.321278 | I12: 11.319716 | J12: 11.341479 | K12: 11.426846 | L12: 11.590858 | M12: 11.667065 | N12: 11.739606 | O12: 11.845197 | P12: 11.928768 | Q12: 12.037337 | R12: 12.171743 | S12: 12.344884 | T12: 12.542388 | U12: 12.744263 | V12: 12.948697 | W12: 13.155006 | X12: 13.368374 | Y12: 13.584894 | Z12: 13.792482 | AA12: 13.995644 | AB12: 14.177751 | AC12: 14.346798 | AD12: 14.50079 | AE12: 14.635315 | AF12: 14.753196 | AG12: 14.849927 | AH12: 14.925963 | AI12: 14.982421 | AJ12: 15.021443 | AK12: 15.045384 | AL12: 15.053828 | AM12: 15.04638 | AN12: 15.023052 | AO12: 14.992042 | AP12: 14.952787 | AQ12: 14.907449 | AR12: 14.862264 | AS12: 14.816138 | AT12: 14.776028 | AU12: 14.743204 | AV12: 14.71738 | AW12: 14.702883 | AX12: 14.698745 | AY12: 14.704872 | AZ12: 14.723131 | BA12: 14.75621 | BB12: 14.801487 | BC12: 14.857738
C13: Gasto | D13: No contributivas | E13: 0.2275377 | F13: 0.21044781 | G13: 0.21495045 | H13: 0.21073515 | I13: 0.21578824 | J13: 0.22226868 | K13: 0.23121352 | L13: 0.2408851 | M13: 0.2408851 | N13: 0.2408851 | O13: 0.2408851 | P13: 0.2408851 | Q13: 0.2408851 | R13: 0.2408851 | S13: 0.2408851 | T13: 0.2408851 | U13: 0.2408851 | V13: 0.2408851 | W13: 0.2408851 | X13: 0.2408851 | Y13: 0.2408851 | Z13: 0.2408851 | AA13: 0.2408851 | AB13: 0.2408851 | AC13: 0.2408851 | AD13: 0.2408851 | AE13: 0.2408851 | AF13: 0.2408851 | AG13: 0.2408851 | AH13: 0.2408851 | AI13: 0.2408851 | AJ13: 0.2408851 | AK13: 0.2408851 | AL13: 0.2408851 | AM13: 0.2408851 | AN13: 0.2408851 | AO13: 0.2408851 | AP13: 0.2408851 | AQ13: 0.2408851 | AR13: 0.2408851 | AS13: 0.2408851 | AT13: 0.2408851 | AU13: 0.2408851 | AV13: 0.2408851 | AW13: 0.2408851 | AX13: 0.2408851 | AY13: 0.2408851 | AZ13: 0.2408851 | BA13: 0.2408851 | BB13: 0.2408851 | BC13: 0.2408851
D14: Saldo | E14: =+E9+E10-E12-E13 -> -2.4808526 | F14: =+F9+F10-F12-F13 -> -1.1116475 | G14: =+G9+G10-G12-G13 -> -0.7046881 | H14: =+H9+H10-H12-H13 -> -0.73048915 | I14: =+I9+I10-I12-I13 -> -0.44569711 | J14: =+J9+J10-J12-J13 -> -0.27504212 | K14: =+K9+K10-K12-K13 -> -0.27723378 | L14: =+L9+L10-L12-L13 -> -0.26951559 | ... BC14: =+BC9+BC10-BC12-BC13 -> -3.0206727
B15: TOTAL | C15: Ingresos | E15: =+E6+E9+E10 -> 11.53729 | F15: =+F6+F9+F10 -> 12.300695 | G15: =+G6+G9+G10 -> 11.979858 | H15: =+H6+H9+H10 -> 12.1944 | I15: =+I6+I9+I10 -> 12.491701 | J15: =+J6+J9+J10 -> 12.678674 | K15: =+K6+K9+K10 -> 12.777558 | L15: =+L6+L9+L10 -> 12.984962 | ... BC15: =+BC6+BC9+BC10 -> 12.397152
C16: Gastos | E16: =+E7+E12+E13 -> 14.018142 | F16: =+F7+F12+F13 -> 13.412342 | G16: =+G7+G12+G13 -> 12.684546 | H16: =+H7+H12+H13 -> 12.92489 | I16: =+I7+I12+I13 -> 12.937398 | J16: =+J7+J12+J13 -> 12.953716 | K16: =+K7+K12+K13 -> 13.054792 | L16: =+L7+L12+L13 -> 13.254478 | ... BC16: =+BC7+BC12+BC13 -> 15.417825
C17: Saldo | E17: =+E15-E16 -> -2.4808526 | F17: =+F15-F16 -> -1.1116475 | G17: =+G15-G16 -> -0.7046881 | H17: =+H15-H16 -> -0.73048915 | I17: =+I15-I16 -> -0.44569711 | J17: =+J15-J16 -> -0.27504212 | K17: =+K15-K16 -> -0.27723378 | L17: =+L15-L16 -> -0.26951559 | ... BC17: =+BC15-BC16 -> -3.0206727
D18: Transferencias implícitas | E18: =-E17 -> 2.4808526 | F18: =-F17 -> 1.1116475 | G18: =-G17 -> 0.7046881 | H18: =-H17 -> 0.73048915 | I18: =-I17 -> 0.44569711 | J18: =-J17 -> 0.27504212 | K18: =-K17 -> 0.27723378 | L18: =-L17 -> 0.26951559 | ... BC18: =-BC17 -> 3.0206727

Sheet Gráfico 13A
A1: Índice de gráficos
B2: GRÁFICO 13. POBLACIÓN (MILES DE PERSONAS)
B3: GRÁFICO 13A. POBLACIÓN TOTAL
B19: Fuente: | C19: INE, Eurostat y AIReF
B20: Población total
C21: Histórico | D21: AIReF 2026 | E21: Bandas | G21: EUROPOP2025 | H21: AIReF 2025 | I21: EUROPOP2023
B22: 1990 | C22: 38853.227
B23: 1991 | C23: 38881.416
B24: 1992 | C24: 39051.336
B25: 1993 | C25: 39264.034
B26: 1994 | C26: 39458.489
B27: 1995 | C27: 39639.726
B28: 1996 | C28: 39808.374
B29: 1997 | C29: 39971.329
B30: 1998 | C30: 40143.449
B31: 1999 | C31: 40303.568
B32: 2000 | C32: 40470.182
B33: 2001 | C33: 40665.545
... B53: 2021 | C53: 47400.798
B54: 2022 | C54: 47486.727 | I54: 47432.893
B55: 2023 | C55: 48085.361 | I55: 47980.384
B56: 2024 | C56: 48619.695 | H56: 48619.695 | I56: 48346.319
B57: 2025 | C57: 49128.297 | D57: 49128.297 | E57: 49128.297 | F57: 49128.297 | G57: 49128.297 | H57: 49081.526 | I57: 48614.06
B58: 2026 | D58: 49570.436 | E58: 49632.468 | F58: 49507.656 | G58: 49570.728 | H58: 49371.252 | I58: 48822.977
B59: 2027 | D59: 50055.838 | E59: 50187.34 | F59: 49922.588 | G59: 49976.787 | H59: 49618.267 | I59: 48973.279
B60: 2028 | D60: 50548.751 | E60: 50756.721 | F60: 50336.295 | G60: 50341.56 | H60: 49811.212 | I60: 49069.647
B61: 2029 | D61: 51021.979 | E61: 51312.201 | F61: 50724.664 | G61: 50665.174 | H61: 49976.081 | I61: 49167.929
B62: 2030 | D62: 51394.484 | E62: 51770.831 | F62: 51006.683 | G62: 50947.559 | H62: 50119.31 | I62: 49266.93
B63: 2031 | D63: 51664.574 | E63: 52130.225 | F63: 51183.116 | G63: 51188.48 | H63: 50246.289 | I63: 49363.835
B64: 2032 | D64: 51876.404 | E64: 52433.272 | F64: 51297.52 | G64: 51388.67 | H64: 50363.793 | I64: 49460.401
B65: 2033 | D65: 52042.12 | E65: 52692.716 | F65: 51363.553 | G65: 51588.777 | H65: 50475.535 | I65: 49558.8
B66: 2034 | D66: 52162.939 | E66: 52908.896 | F66: 51383.414 | G66: 51784.85 | H66: 50584.666 | I66: 49656.906
B67: 2035 | D67: 52260.348 | E67: 53103.114 | F67: 51378.372 | G67: 51977.041 | H67: 50691.139 | I67: 49760.92
B68: 2036 | D68: 52333.543 | E68: 53274.398 | F68: 51347.896 | G68: 52165.359 | H68: 50796.355 | I68: 49863.657
B69: 2037 | D69: 52397.903 | E69: 53438.024 | F69: 51307.048 | G69: 52350.887 | H69: 50901.155 | I69: 49963.357
... B82: 2050 | D82: 52728.898 | E82: 55065.464 | F82: 50258.766 | G82: 53877.467 | H82: 52094.597 | I82: 50460.161

Sheet Gráfico 13B
A1: Índice de gráficos
B2: GRÁFICO 13. POBLACIÓN (MILES DE PERSONAS)
B3: GRÁFICO 13B. POBLACIÓN DE 15-74 AÑOS
B18: Fuente: | C18: INE, Eurostat y AIReF
B19: Población en edad de trabajar
C20: Histórico | D20: AIReF 2026 | E20: Bandas | G20: EUROPOP2025 | H20: AIReF 2025 | I20: EUROPOP2023
B21: 1990 | C21: 28828.563
B22: 1991 | C22: 29103.713
B23: 1992 | C23: 29482.022
B24: 1993 | C24: 29861.394
B25: 1994 | C25: 30225.709
B26: 1995 | C26: 30565.552
B27: 1996 | C27: 30848.249
B28: 1997 | C28: 31094.288
B29: 1998 | C29: 31304.887
B30: 1999 | C30: 31488.156
B31: 2000 | C31: 31650.055
B32: 2001 | C32: 31795.799
... B52: 2021 | C52: 36059.396
B53: 2022 | C53: 36196.474 | I53: 36069.646
B54: 2023 | C54: 36763.28 | I54: 36574.611
B55: 2024 | C55: 37266.661 | H55: 37266.661 | I55: 36928.514
B56: 2025 | C56: 37745.287 | D56: 37745.287 | E56: 37745.287 | F56: 37745.287 | G56: 37745.287 | H56: 37697.449 | I56: 37204.985
B57: 2026 | D57: 38177.326 | E57: 38210.985 | F57: 38143.34 | G57: 38185.648 | H57: 37998.549 | I57: 37444.61
B58: 2027 | D58: 38633.313 | E58: 38702.254 | F58: 38563.455 | G58: 38581.256 | H58: 38249.454 | I58: 37626.201
B59: 2028 | D59: 39064.036 | E59: 39169.915 | F59: 38956.211 | G59: 38913.643 | H59: 38421.766 | I59: 37721.644
B60: 2029 | D60: 39459.078 | E60: 39602.686 | F60: 39312.087 | G60: 39192.114 | H60: 38549.914 | I60: 37795.859
B61: 2030 | D61: 39782.755 | E61: 39964.574 | F61: 39595.747 | G61: 39448.752 | H61: 38669.71 | I61: 37878.077
B62: 2031 | D62: 39999.784 | E62: 40220.148 | F62: 39772.108 | G62: 39647.303 | H62: 38753.104 | I62: 37932.661
B63: 2032 | D63: 40150.978 | E63: 40410.276 | F63: 39881.966 | G63: 39791.371 | H63: 38808.706 | I63: 37962.593
B64: 2033 | D64: 40217.445 | E64: 40515.742 | F64: 39906.818 | G64: 39881.547 | H64: 38810.229 | I64: 37939.343
B65: 2034 | D65: 40220.334 | E65: 40557.766 | F65: 39867.755 | G65: 39933.183 | H65: 38778.97 | I65: 37880.087
B66: 2035 | D66: 40183.979 | E66: 40560.594 | F66: 39789.228 | G66: 39954.748 | H66: 38722.54 | I66: 37799.883
B67: 2036 | D67: 40104.576 | E67: 40520.304 | F67: 39667.585 | G67: 39942.102 | H67: 38637.724 | I67: 37687.162
B68: 2037 | D68: 40023.588 | E68: 40478.502 | F68: 39544.132 | G68: 39927.38 | H68: 38555.958 | I68: 37573.29
... B81: 2050 | D81: 37966.416 | E81: 38989.05 | F81: 36875.106 | G81: 38321.532 | H81: 36718.645 | I81: 34998.546

Sheet Gráfico 14A
A1: Índice de gráficos
B2: GRÁFICO 14. TASA DE DEPENDENCIA (% DE LA POBLACIÓN ENTRE 15 Y 74 AÑOS)
B3: GRÁFICO 14A. DESCOMPOSICIÓN DE LA TASA DE DEPENDENCIA
B18: Fuente: | C18: INE y AIReF
B19: Tasa de dependencia
C20: Total | D20: < 15 años | E20: > 74 años
B21: 2002 | C21: =+D21+E21 -> 28.054612 | D21: 18.577039 | E21: 9.4775731
B22: 2003 | C22: =+D22+E22 -> 28.177922 | D22: 18.549583 | E22: 9.6283393
B23: 2004 | C23: =+D23+E23 -> 28.420995 | D23: 18.603893 | E23: 9.8171022
B24: 2005 | C24: =+D24+E24 -> 28.617358 | D24: 18.601201 | E24: 10.016157
B25: 2006 | C25: =+D25+E25 -> 28.925609 | D25: 18.690769 | E25: 10.23484
B26: 2007 | C26: =+D26+E26 -> 29.296793 | D26: 18.840453 | E26: 10.456341
B27: 2008 | C27: =+D27+E27 -> 29.620278 | D27: 18.966299 | E27: 10.653979
B28: 2009 | C28: =+D28+E28 -> 30.173302 | D28: 19.242874 | E28: 10.930428
B29: 2010 | C29: =+D29+E29 -> 30.742178 | D29: 19.501071 | E29: 11.241106
B30: 2011 | C30: =+D30+E30 -> 31.297555 | D30: 19.732963 | E30: 11.564592
B31: 2012 | C31: =+D31+E31 -> 31.821817 | D31: 19.925909 | E31: 11.895908
B32: 2013 | C32: =+D32+E32 -> 32.114665 | D32: 20.025394 | E32: 12.089271
... B69: 2050 | C69: =+D69+E69 -> 38.883002 | D69: 14.428282 | E69: 24.454719

Sheet Gráfico 14B
A1: Índice de gráficos
B2: GRÁFICO 14. TASA DE DEPENDENCIA (% DE LA POBLACIÓN ENTRE 15 Y 74 AÑOS)
B3: GRÁFICO 14B. COMPRATIVA DE TASAS DE DEPENDENCIA
B20: Fuente: | C20: INE, Eurostat y AIReF
B21: Tasa de dependencia
C22: Total | G22: <15
C23: Histórico | D23: AIReF 2026 | E23: EUROPOP2025 | F23: AIReF 2025 | G23: Histórico | H23: AIReF 2026 | I23: EUROPOP2025 | J23: AIReF 2025
B24: 2002 | C24: 28.054612 | G24: 18.577039
B25: 2003 | C25: 28.177922 | G25: 18.549583
B26: 2004 | C26: 28.420995 | G26: 18.603893
B27: 2005 | C27: 28.617358 | G27: 18.601201
B28: 2006 | C28: 28.925609 | G28: 18.690769
B29: 2007 | C29: 29.296793 | G29: 18.840453
B30: 2008 | C30: 29.620278 | G30: 18.966299
B31: 2009 | C31: 30.173302 | G31: 19.242874
B32: 2010 | C32: 30.742178 | G32: 19.501071
B33: 2011 | C33: 31.297555 | G33: 19.732963
B34: 2012 | C34: 31.821817 | G34: 19.925909
B35: 2013 | C35: 32.114665 | G35: 20.025394
... B45: 2023 | C45: 30.797255 | G45: 17.781914
B46: 2024 | C46: 30.464318 | F46: 30.464318 | G46: 17.255039 | J46: 17.255039
B47: 2025 | C47: 30.157434 | D47: 30.157434 | E47: 30.157434 | F47: 30.198533 | G47: 16.807563 | H47: 16.807563 | I47: 16.807563 | J47: 16.797654
B48: 2026 | D48: 29.842607 | E48: 29.815076 | F48: 29.92931 | H48: 16.352661 | I48: 16.384064 | J48: 16.358357
B49: 2027 | D49: 29.566517 | E49: 29.536444 | F49: 29.722811 | H49: 15.934379 | I49: 15.978023 | J49: 15.960737
B50: 2028 | D50: 29.399714 | E50: 29.367379 | F50: 29.643212 | H50: 15.562771 | I50: 15.603276 | J50: 15.60977
B51: 2029 | D51: 29.303523 | E51: 29.273899 | F51: 29.639928 | H51: 15.265978 | I51: 15.294411 | J51: 15.335606
B52: 2030 | D52: 29.187845 | E52: 29.148722 | F52: 29.608704 | H52: 14.95114 | I52: 14.961312 | J52: 15.050077
B53: 2031 | D53: 29.162133 | E53: 29.109614 | F53: 29.657458 | H53: 14.657734 | I53: 14.651478 | J53: 14.794921
B54: 2032 | D54: 29.20334 | E54: 29.145261 | F54: 29.774471 | H54: 14.39446 | I54: 14.374227 | J54: 14.578881
B55: 2033 | D55: 29.401853 | E55: 29.355005 | F55: 30.057297 | H55: 14.192792 | I55: 14.17532 | J55: 14.438456
B56: 2034 | D56: 29.692952 | E56: 29.678744 | F56: 30.443552 | H56: 14.050342 | I56: 14.061416 | J56: 14.374919
B57: 2035 | D57: 30.052694 | E57: 30.089773 | F57: 30.908609 | H57: 13.951007 | I57: 14.0102 | J57: 14.366781
B58: 2036 | D58: 30.492698 | E58: 30.602438 | F58: 31.46829 | H58: 13.897833 | I58: 14.026302 | J58: 14.421037
B59: 2037 | D59: 30.917556 | E59: 31.115257 | F59: 32.018909 | H59: 13.849228 | I59: 14.063445 | J59: 14.488093
... B72: 2050 | D72: 38.883002 | E72: 40.593197 | F72: 41.875055 | H72: 14.428282 | I72: 15.733372 | J72: 16.893498

Sheet Gráfico 15
A1: Índice de gráficos
B3: GRÁFICO 15. CRECIMIENTO PROMEDIO DEL PIB POTENCIAL (%, 2022-2050)
C6: Enter labels below: | D6: Enter values below: | E6: Cumulative | F6: Start & End | G6: Before | H6: After | I6: Data label position
C7: Mix edad | D7: 0.17376152 | E7: 0.17376152 | F7: 0.17376152
C8: Intensidad | D8: 0.33018589 | E8: 0.50394741 | G8: 0.17376152 | H8: 0.50394741 | I8: 0.50394741
C9: Productividad | D9: 0.97191624 | E9: 1.4758637 | G9: 0.50394741 | H9: 1.4758637 | I9: 1.4758637
C10: PIB | D10: 1.4758637 | F10: 1.4758637
K35: Fuente: | L35: AIReF

Sheet Gráfico 16
B3: GRÁFICO 16. TASA DE PARTICIPACIÓN (% POBLACIÓN 15-74 AÑOS)
B5: YEAR | C5: Previsión | D5: Variable
B6: 1980 | C6: 0 | D6: 54.692333
B7: 1981 | C7: 0 | D7: 54.13728
B8: 1982 | C8: 0 | D8: 53.640218
B9: 1983 | C9: 0 | D9: 53.244388
B10: 1984 | C10: 0 | D10: 53.100922
B11: 1985 | C11: 0 | D11: 53.313571
B12: 1986 | C12: 0 | D12: 53.908011
B13: 1987 | C13: 0 | D13: 54.776777
B14: 1988 | C14: 0 | D14: 55.665027
B15: 1989 | C15: 0 | D15: 56.438607
B16: 1990 | C16: 0 | D16: 57.06653
B17: 1991 | C17: 0 | D17: 57.541136
... B23: 1997 | C23: 0 | D23: 59.086658
B24: 1998 | C24: 0 | D24: 59.479823 | F24: Fuente: | G24: AIReF
B25: 1999 | C25: 0 | D25: 59.971141
B26: 2000 | C26: 0 | D26: 60.558669
B27: 2001 | C27: 0 | D27: 61.218212
B28: 2002 | C28: 0 | D28: 61.991165
B29: 2003 | C29: 0 | D29: 62.851306
B30: 2004 | C30: 0 | D30: 63.765556
B31: 2005 | C31: 0 | D31: 64.708085
B32: 2006 | C32: 0 | D32: 65.666157
B33: 2007 | C33: 0 | D33: 66.588075
B34: 2008 | C34: 0 | D34: 67.408118
